<?xml version="1.0" encoding="UTF-8"?>
<testng-results ignored="0" total="4" passed="2" failed="2" skipped="0">
  <reporter-output>
  </reporter-output>
  <suite started-at="2024-09-02T01:40:39 IST" name="Suite" finished-at="2024-09-02T01:40:47 IST" duration-ms="8914">
    <groups>
    </groups>
    <test started-at="2024-09-02T01:40:39 IST" name="Test" finished-at="2024-09-02T01:40:47 IST" duration-ms="8914">
      <class name="api.test.UserTests">
        <test-method is-config="true" signature="setUp()[pri:0, instance:api.test.UserTests@663c9e7a]" started-at="2024-09-02T01:40:39 IST" name="setUp" finished-at="2024-09-02T01:40:39 IST" duration-ms="188" status="PASS">
          <reporter-output>
          </reporter-output>
        </test-method> <!-- setUp -->
        <test-method is-config="true" signature="setUp()[pri:0, instance:api.test.UserTests@663c9e7a]" started-at="2024-09-02T01:40:39 IST" name="setUp" finished-at="2024-09-02T01:40:39 IST" duration-ms="39" status="PASS">
          <reporter-output>
          </reporter-output>
        </test-method> <!-- setUp -->
        <test-method signature="testPostUser()[pri:1, instance:api.test.UserTests@663c9e7a]" started-at="2024-09-02T01:40:39 IST" name="testPostUser" finished-at="2024-09-02T01:40:42 IST" duration-ms="2802" status="PASS">
          <reporter-output>
          </reporter-output>
        </test-method> <!-- testPostUser -->
        <test-method is-config="true" signature="setUp()[pri:0, instance:api.test.UserTests@663c9e7a]" started-at="2024-09-02T01:40:42 IST" name="setUp" finished-at="2024-09-02T01:40:42 IST" duration-ms="49" status="PASS">
          <reporter-output>
          </reporter-output>
        </test-method> <!-- setUp -->
        <test-method signature="testGetUserByUserName()[pri:2, instance:api.test.UserTests@663c9e7a]" started-at="2024-09-02T01:40:42 IST" name="testGetUserByUserName" finished-at="2024-09-02T01:40:43 IST" duration-ms="1514" status="FAIL">
          <exception class="java.lang.AssertionError">
            <message>
              <![CDATA[expected:<404> but was:<200>]]>
            </message>
            <full-stacktrace>
              <![CDATA[java.lang.AssertionError: expected:<404> but was:<200>
at org.testng.AssertJUnit.fail(AssertJUnit.java:65)
at org.testng.AssertJUnit.failNotEquals(AssertJUnit.java:467)
at org.testng.AssertJUnit.assertEquals(AssertJUnit.java:88)
at org.testng.AssertJUnit.assertEquals(AssertJUnit.java:318)
at org.testng.AssertJUnit.assertEquals(AssertJUnit.java:328)
at api.test.UserTests.testGetUserByUserName(UserTests.java:50)
at java.base/jdk.internal.reflect.NativeMethodAccessorImpl.invoke0(Native Method)
at java.base/jdk.internal.reflect.NativeMethodAccessorImpl.invoke(NativeMethodAccessorImpl.java:78)
at java.base/jdk.internal.reflect.DelegatingMethodAccessorImpl.invoke(DelegatingMethodAccessorImpl.java:43)
at java.base/java.lang.reflect.Method.invoke(Method.java:567)
at org.testng.internal.invokers.MethodInvocationHelper.invokeMethod(MethodInvocationHelper.java:141)
at org.testng.internal.invokers.TestInvoker.invokeMethod(TestInvoker.java:686)
at org.testng.internal.invokers.TestInvoker.invokeTestMethod(TestInvoker.java:230)
at org.testng.internal.invokers.MethodRunner.runInSequence(MethodRunner.java:63)
at org.testng.internal.invokers.TestInvoker$MethodInvocationAgent.invoke(TestInvoker.java:992)
at org.testng.internal.invokers.TestInvoker.invokeTestMethods(TestInvoker.java:203)
at org.testng.internal.invokers.TestMethodWorker.invokeTestMethods(TestMethodWorker.java:154)
at org.testng.internal.invokers.TestMethodWorker.run(TestMethodWorker.java:134)
at java.base/java.util.ArrayList.forEach(ArrayList.java:1511)
at org.testng.TestRunner.privateRun(TestRunner.java:739)
at org.testng.TestRunner.run(TestRunner.java:614)
at org.testng.SuiteRunner.runTest(SuiteRunner.java:421)
at org.testng.SuiteRunner.runSequentially(SuiteRunner.java:413)
at org.testng.SuiteRunner.privateRun(SuiteRunner.java:373)
at org.testng.SuiteRunner.run(SuiteRunner.java:312)
at org.testng.SuiteRunnerWorker.runSuite(SuiteRunnerWorker.java:52)
at org.testng.SuiteRunnerWorker.run(SuiteRunnerWorker.java:95)
at org.testng.TestNG.runSuitesSequentially(TestNG.java:1274)
at org.testng.TestNG.runSuitesLocally(TestNG.java:1208)
at org.testng.TestNG.runSuites(TestNG.java:1112)
at org.testng.TestNG.run(TestNG.java:1079)
at org.testng.remote.AbstractRemoteTestNG.run(AbstractRemoteTestNG.java:115)
at org.testng.remote.RemoteTestNG.initAndRun(RemoteTestNG.java:293)
at org.testng.remote.RemoteTestNG.main(RemoteTestNG.java:91)
]]>
            </full-stacktrace>
          </exception> <!-- java.lang.AssertionError -->
          <reporter-output>
          </reporter-output>
        </test-method> <!-- testGetUserByUserName -->
        <test-method is-config="true" signature="setUp()[pri:0, instance:api.test.UserTests@663c9e7a]" started-at="2024-09-02T01:40:43 IST" name="setUp" finished-at="2024-09-02T01:40:43 IST" duration-ms="31" status="PASS">
          <reporter-output>
          </reporter-output>
        </test-method> <!-- setUp -->
        <test-method signature="testUpdateUser()[pri:3, instance:api.test.UserTests@663c9e7a]" started-at="2024-09-02T01:40:43 IST" name="testUpdateUser" finished-at="2024-09-02T01:40:46 IST" duration-ms="2745" status="PASS">
          <reporter-output>
          </reporter-output>
        </test-method> <!-- testUpdateUser -->
        <test-method is-config="true" signature="setUp()[pri:0, instance:api.test.UserTests@663c9e7a]" started-at="2024-09-02T01:40:46 IST" name="setUp" finished-at="2024-09-02T01:40:46 IST" duration-ms="22" status="PASS">
          <reporter-output>
          </reporter-output>
        </test-method> <!-- setUp -->
        <test-method signature="testDeleteUserByUserName()[pri:4, instance:api.test.UserTests@663c9e7a]" started-at="2024-09-02T01:40:46 IST" name="testDeleteUserByUserName" finished-at="2024-09-02T01:40:47 IST" duration-ms="1283" status="FAIL">
          <exception class="java.lang.AssertionError">
            <message>
              <![CDATA[expected:<404> but was:<200>]]>
            </message>
            <full-stacktrace>
              <![CDATA[java.lang.AssertionError: expected:<404> but was:<200>
at org.testng.AssertJUnit.fail(AssertJUnit.java:65)
at org.testng.AssertJUnit.failNotEquals(AssertJUnit.java:467)
at org.testng.AssertJUnit.assertEquals(AssertJUnit.java:88)
at org.testng.AssertJUnit.assertEquals(AssertJUnit.java:318)
at org.testng.AssertJUnit.assertEquals(AssertJUnit.java:328)
at api.test.UserTests.testDeleteUserByUserName(UserTests.java:76)
at java.base/jdk.internal.reflect.NativeMethodAccessorImpl.invoke0(Native Method)
at java.base/jdk.internal.reflect.NativeMethodAccessorImpl.invoke(NativeMethodAccessorImpl.java:78)
at java.base/jdk.internal.reflect.DelegatingMethodAccessorImpl.invoke(DelegatingMethodAccessorImpl.java:43)
at java.base/java.lang.reflect.Method.invoke(Method.java:567)
at org.testng.internal.invokers.MethodInvocationHelper.invokeMethod(MethodInvocationHelper.java:141)
at org.testng.internal.invokers.TestInvoker.invokeMethod(TestInvoker.java:686)
at org.testng.internal.invokers.TestInvoker.invokeTestMethod(TestInvoker.java:230)
at org.testng.internal.invokers.MethodRunner.runInSequence(MethodRunner.java:63)
at org.testng.internal.invokers.TestInvoker$MethodInvocationAgent.invoke(TestInvoker.java:992)
at org.testng.internal.invokers.TestInvoker.invokeTestMethods(TestInvoker.java:203)
at org.testng.internal.invokers.TestMethodWorker.invokeTestMethods(TestMethodWorker.java:154)
at org.testng.internal.invokers.TestMethodWorker.run(TestMethodWorker.java:134)
at java.base/java.util.ArrayList.forEach(ArrayList.java:1511)
at org.testng.TestRunner.privateRun(TestRunner.java:739)
at org.testng.TestRunner.run(TestRunner.java:614)
at org.testng.SuiteRunner.runTest(SuiteRunner.java:421)
at org.testng.SuiteRunner.runSequentially(SuiteRunner.java:413)
at org.testng.SuiteRunner.privateRun(SuiteRunner.java:373)
at org.testng.SuiteRunner.run(SuiteRunner.java:312)
at org.testng.SuiteRunnerWorker.runSuite(SuiteRunnerWorker.java:52)
at org.testng.SuiteRunnerWorker.run(SuiteRunnerWorker.java:95)
at org.testng.TestNG.runSuitesSequentially(TestNG.java:1274)
at org.testng.TestNG.runSuitesLocally(TestNG.java:1208)
at org.testng.TestNG.runSuites(TestNG.java:1112)
at org.testng.TestNG.run(TestNG.java:1079)
at org.testng.remote.AbstractRemoteTestNG.run(AbstractRemoteTestNG.java:115)
at org.testng.remote.RemoteTestNG.initAndRun(RemoteTestNG.java:293)
at org.testng.remote.RemoteTestNG.main(RemoteTestNG.java:91)
]]>
            </full-stacktrace>
          </exception> <!-- java.lang.AssertionError -->
          <reporter-output>
          </reporter-output>
        </test-method> <!-- testDeleteUserByUserName -->
      </class> <!-- api.test.UserTests -->
    </test> <!-- Test -->
  </suite> <!-- Suite -->
</testng-results>
